Workbook

Sheet 00_Control_Panel
B2: Warby Parker - 3-Statement Model
B4: Scenario Selector | C4: Best | D4: =IF(OR(C4="Base",C4="Best",C4="Worst"),"✓ Valid","⚠ INVALID SCENARIO") -> ✓ Valid
B5: Valid scenarios: | C5: Base, Best, Worst

Sheet 01_Assumptions
A1: Assumptions - Driver Inputs
A3: Section A: Historical Ratios (FY2021-FY2025)
A5: Driver | B5: 2021 | C5: 2022 | D5: 2023 | E5: 2024 | F5: 2025
A6: revenue_growth_pct | B6: =IF(INDEX('10_Data_Sources'!$B$159:$F$171,MATCH($A6,'10_Data_Sources'!$A$159:$A$171,0),MATCH(B$5,'10_Data_Sources'!$B$158:$F$158,0))="","–",INDEX('10_Data_Sources'!$B$159:$F$171,MATCH($A6,'10_Data_Sources'!$A$159:$A$171,0),MATCH(B$5,'10_Data_Sources'!$B$158:$F$158,0))) -> – | C6: =IF(INDEX('10_Data_Sources'!$B$159:$F$171,MATCH($A6,'10_Data_Sources'!$A$159:$A$171,0),MATCH(C$5,'10_Data_Sources'!$B$158:$F$158,0))="","–",INDEX('10_Data_Sources'!$B$159:$F$171,MATCH($A6,'10_Data_Sources'!$A$159:$A$171,0),MATCH(C$5,'10_Data_Sources'!$B$158:$F$158,0))) -> 0.10598042 | D6: =IF(INDEX('10_Data_Sources'!$B$159:$F$171,MATCH($A6,'10_Data_Sources'!$A$159:$A$171,0),MATCH(D$5,'10_Data_Sources'!$B$158:$F$158,0))="","–",INDEX('10_Data_Sources'!$B$159:$F$171,MATCH($A6,'10_Data_Sources'!$A$159:$A$171,0),MATCH(D$5,'10_Data_Sources'!$B$158:$F$158,0))) -> 0.11979863 | E6: =IF(INDEX('10_Data_Sources'!$B$159:$F$171,MATCH($A6,'10_Data_Sources'!$A$159:$A$171,0),MATCH(E$5,'10_Data_Sources'!$B$158:$F$158,0))="","–",INDEX('10_Data_Sources'!$B$159:$F$171,MATCH($A6,'10_Data_Sources'!$A$159:$A$171,0),MATCH(E$5,'10_Data_Sources'!$B$158:$F$158,0))) -> 0.15162034 | F6: =IF(INDEX('10_Data_Sources'!$B$159:$F$171,MATCH($A6,'10_Data_Sources'!$A$159:$A$171,0),MATCH(F$5,'10_Data_Sources'!$B$158:$F$158,0))="","–",INDEX('10_Data_Sources'!$B$159:$F$171,MATCH($A6,'10_Data_Sources'!$A$159:$A$171,0),MATCH(F$5,'10_Data_Sources'!$B$158:$F$158,0))) -> 0.13041364
A7: gross_margin_pct | B7: =IF(INDEX('10_Data_Sources'!$B$159:$F$171,MATCH($A7,'10_Data_Sources'!$A$159:$A$171,0),MATCH(B$5,'10_Data_Sources'!$B$158:$F$158,0))="","–",INDEX('10_Data_Sources'!$B$159:$F$171,MATCH($A7,'10_Data_Sources'!$A$159:$A$171,0),MATCH(B$5,'10_Data_Sources'!$B$158:$F$158,0))) -> 0.5875558 | C7: =IF(INDEX('10_Data_Sources'!$B$159:$F$171,MATCH($A7,'10_Data_Sources'!$A$159:$A$171,0),MATCH(C$5,'10_Data_Sources'!$B$158:$F$158,0))="","–",INDEX('10_Data_Sources'!$B$159:$F$171,MATCH($A7,'10_Data_Sources'!$A$159:$A$171,0),MATCH(C$5,'10_Data_Sources'!$B$158:$F$158,0))) -> 0.57023099 | D7: =IF(INDEX('10_Data_Sources'!$B$159:$F$171,MATCH($A7,'10_Data_Sources'!$A$159:$A$171,0),MATCH(D$5,'10_Data_Sources'!$B$158:$F$158,0))="","–",INDEX('10_Data_Sources'!$B$159:$F$171,MATCH($A7,'10_Data_Sources'!$A$159:$A$171,0),MATCH(D$5,'10_Data_Sources'!$B$158:$F$158,0))) -> 0.54530171 | E7: =IF(INDEX('10_Data_Sources'!$B$159:$F$171,MATCH($A7,'10_Data_Sources'!$A$159:$A$171,0),MATCH(E$5,'10_Data_Sources'!$B$158:$F$158,0))="","–",INDEX('10_Data_Sources'!$B$159:$F$171,MATCH($A7,'10_Data_Sources'!$A$159:$A$171,0),MATCH(E$5,'10_Data_Sources'!$B$158:$F$158,0))) -> 0.5533848 | F7: =IF(INDEX('10_Data_Sources'!$B$159:$F$171,MATCH($A7,'10_Data_Sources'!$A$159:$A$171,0),MATCH(F$5,'10_Data_Sources'!$B$158:$F$158,0))="","–",INDEX('10_Data_Sources'!$B$159:$F$171,MATCH($A7,'10_Data_Sources'!$A$159:$A$171,0),MATCH(F$5,'10_Data_Sources'!$B$158:$F$158,0))) -> 0.53971362
A8: cogs_pct_revenue | B8: =IF(INDEX('10_Data_Sources'!$B$159:$F$171,MATCH($A8,'10_Data_Sources'!$A$159:$A$171,0),MATCH(B$5,'10_Data_Sources'!$B$158:$F$158,0))="","–",INDEX('10_Data_Sources'!$B$159:$F$171,MATCH($A8,'10_Data_Sources'!$A$159:$A$171,0),MATCH(B$5,'10_Data_Sources'!$B$158:$F$158,0))) -> 0.4124442 | C8: =IF(INDEX('10_Data_Sources'!$B$159:$F$171,MATCH($A8,'10_Data_Sources'!$A$159:$A$171,0),MATCH(C$5,'10_Data_Sources'!$B$158:$F$158,0))="","–",INDEX('10_Data_Sources'!$B$159:$F$171,MATCH($A8,'10_Data_Sources'!$A$159:$A$171,0),MATCH(C$5,'10_Data_Sources'!$B$158:$F$158,0))) -> 0.42976901 | D8: =IF(INDEX('10_Data_Sources'!$B$159:$F$171,MATCH($A8,'10_Data_Sources'!$A$159:$A$171,0),MATCH(D$5,'10_Data_Sources'!$B$158:$F$158,0))="","–",INDEX('10_Data_Sources'!$B$159:$F$171,MATCH($A8,'10_Data_Sources'!$A$159:$A$171,0),MATCH(D$5,'10_Data_Sources'!$B$158:$F$158,0))) -> 0.45469829 | E8: =IF(INDEX('10_Data_Sources'!$B$159:$F$171,MATCH($A8,'10_Data_Sources'!$A$159:$A$171,0),MATCH(E$5,'10_Data_Sources'!$B$158:$F$158,0))="","–",INDEX('10_Data_Sources'!$B$159:$F$171,MATCH($A8,'10_Data_Sources'!$A$159:$A$171,0),MATCH(E$5,'10_Data_Sources'!$B$158:$F$158,0))) -> 0.4466152 | F8: =IF(INDEX('10_Data_Sources'!$B$159:$F$171,MATCH($A8,'10_Data_Sources'!$A$159:$A$171,0),MATCH(F$5,'10_Data_Sources'!$B$158:$F$158,0))="","–",INDEX('10_Data_Sources'!$B$159:$F$171,MATCH($A8,'10_Data_Sources'!$A$159:$A$171,0),MATCH(F$5,'10_Data_Sources'!$B$158:$F$158,0))) -> 0.46028638
A9: sga_pct_revenue | B9: =IF(INDEX('10_Data_Sources'!$B$159:$F$171,MATCH($A9,'10_Data_Sources'!$A$159:$A$171,0),MATCH(B$5,'10_Data_Sources'!$B$158:$F$158,0))="","–",INDEX('10_Data_Sources'!$B$159:$F$171,MATCH($A9,'10_Data_Sources'!$A$159:$A$171,0),MATCH(B$5,'10_Data_Sources'!$B$158:$F$158,0))) -> 0.85320212 | C9: =IF(INDEX('10_Data_Sources'!$B$159:$F$171,MATCH($A9,'10_Data_Sources'!$A$159:$A$171,0),MATCH(C$5,'10_Data_Sources'!$B$158:$F$158,0))="","–",INDEX('10_Data_Sources'!$B$159:$F$171,MATCH($A9,'10_Data_Sources'!$A$159:$A$171,0),MATCH(C$5,'10_Data_Sources'!$B$158:$F$158,0))) -> 0.75615437 | D9: =IF(INDEX('10_Data_Sources'!$B$159:$F$171,MATCH($A9,'10_Data_Sources'!$A$159:$A$171,0),MATCH(D$5,'10_Data_Sources'!$B$158:$F$158,0))="","–",INDEX('10_Data_Sources'!$B$159:$F$171,MATCH($A9,'10_Data_Sources'!$A$159:$A$171,0),MATCH(D$5,'10_Data_Sources'!$B$158:$F$158,0))) -> 0.65279613 | E9: =IF(INDEX('10_Data_Sources'!$B$159:$F$171,MATCH($A9,'10_Data_Sources'!$A$159:$A$171,0),MATCH(E$5,'10_Data_Sources'!$B$158:$F$158,0))="","–",INDEX('10_Data_Sources'!$B$159:$F$171,MATCH($A9,'10_Data_Sources'!$A$159:$A$171,0),MATCH(E$5,'10_Data_Sources'!$B$158:$F$158,0))) -> 0.59242463 | F9: =IF(INDEX('10_Data_Sources'!$B$159:$F$171,MATCH($A9,'10_Data_Sources'!$A$159:$A$171,0),MATCH(F$5,'10_Data_Sources'!$B$158:$F$158,0))="","–",INDEX('10_Data_Sources'!$B$159:$F$171,MATCH($A9,'10_Data_Sources'!$A$159:$A$171,0),MATCH(F$5,'10_Data_Sources'!$B$158:$F$158,0))) -> 0.54583355
A10: operating_margin_pct | B10: =IF(INDEX('10_Data_Sources'!$B$159:$F$171,MATCH($A10,'10_Data_Sources'!$A$159:$A$171,0),MATCH(B$5,'10_Data_Sources'!$B$158:$F$158,0))="","–",INDEX('10_Data_Sources'!$B$159:$F$171,MATCH($A10,'10_Data_Sources'!$A$159:$A$171,0),MATCH(B$5,'10_Data_Sources'!$B$158:$F$158,0))) -> -0.26564632 | C10: =IF(INDEX('10_Data_Sources'!$B$159:$F$171,MATCH($A10,'10_Data_Sources'!$A$159:$A$171,0),MATCH(C$5,'10_Data_Sources'!$B$158:$F$158,0))="","–",INDEX('10_Data_Sources'!$B$159:$F$171,MATCH($A10,'10_Data_Sources'!$A$159:$A$171,0),MATCH(C$5,'10_Data_Sources'!$B$158:$F$158,0))) -> -0.18592337 | D10: =IF(INDEX('10_Data_Sources'!$B$159:$F$171,MATCH($A10,'10_Data_Sources'!$A$159:$A$171,0),MATCH(D$5,'10_Data_Sources'!$B$158:$F$158,0))="","–",INDEX('10_Data_Sources'!$B$159:$F$171,MATCH($A10,'10_Data_Sources'!$A$159:$A$171,0),MATCH(D$5,'10_Data_Sources'!$B$158:$F$158,0))) -> -0.10749442 | E10: =IF(INDEX('10_Data_Sources'!$B$159:$F$171,MATCH($A10,'10_Data_Sources'!$A$159:$A$171,0),MATCH(E$5,'10_Data_Sources'!$B$158:$F$158,0))="","–",INDEX('10_Data_Sources'!$B$159:$F$171,MATCH($A10,'10_Data_Sources'!$A$159:$A$171,0),MATCH(E$5,'10_Data_Sources'!$B$158:$F$158,0))) -> -0.039039822 | F10: =IF(INDEX('10_Data_Sources'!$B$159:$F$171,MATCH($A10,'10_Data_Sources'!$A$159:$A$171,0),MATCH(F$5,'10_Data_Sources'!$B$158:$F$158,0))="","–",INDEX('10_Data_Sources'!$B$159:$F$171,MATCH($A10,'10_Data_Sources'!$A$159:$A$171,0),MATCH(F$5,'10_Data_Sources'!$B$158:$F$158,0))) -> -0.0061199328
A11: net_margin_pct | B11: =IF(INDEX('10_Data_Sources'!$B$159:$F$171,MATCH($A11,'10_Data_Sources'!$A$159:$A$171,0),MATCH(B$5,'10_Data_Sources'!$B$158:$F$158,0))="","–",INDEX('10_Data_Sources'!$B$159:$F$171,MATCH($A11,'10_Data_Sources'!$A$159:$A$171,0),MATCH(B$5,'10_Data_Sources'!$B$158:$F$158,0))) -> -0.26677429 | C11: =IF(INDEX('10_Data_Sources'!$B$159:$F$171,MATCH($A11,'10_Data_Sources'!$A$159:$A$171,0),MATCH(C$5,'10_Data_Sources'!$B$158:$F$158,0))="","–",INDEX('10_Data_Sources'!$B$159:$F$171,MATCH($A11,'10_Data_Sources'!$A$159:$A$171,0),MATCH(C$5,'10_Data_Sources'!$B$158:$F$158,0))) -> -0.18456911 | D11: =IF(INDEX('10_Data_Sources'!$B$159:$F$171,MATCH($A11,'10_Data_Sources'!$A$159:$A$171,0),MATCH(D$5,'10_Data_Sources'!$B$158:$F$158,0))="","–",INDEX('10_Data_Sources'!$B$159:$F$171,MATCH($A11,'10_Data_Sources'!$A$159:$A$171,0),MATCH(D$5,'10_Data_Sources'!$B$158:$F$158,0))) -> -0.094356976 | E11: =IF(INDEX('10_Data_Sources'!$B$159:$F$171,MATCH($A11,'10_Data_Sources'!$A$159:$A$171,0),MATCH(E$5,'10_Data_Sources'!$B$158:$F$158,0))="","–",INDEX('10_Data_Sources'!$B$159:$F$171,MATCH($A11,'10_Data_Sources'!$A$159:$A$171,0),MATCH(E$5,'10_Data_Sources'!$B$158:$F$158,0))) -> -0.026435373 | F11: =IF(INDEX('10_Data_Sources'!$B$159:$F$171,MATCH($A11,'10_Data_Sources'!$A$159:$A$171,0),MATCH(F$5,'10_Data_Sources'!$B$158:$F$158,0))="","–",INDEX('10_Data_Sources'!$B$159:$F$171,MATCH($A11,'10_Data_Sources'!$A$159:$A$171,0),MATCH(F$5,'10_Data_Sources'!$B$158:$F$158,0))) -> 0.0018820858
A12: effective_tax_rate_pct | B12: =IF(INDEX('10_Data_Sources'!$B$159:$F$171,MATCH($A12,'10_Data_Sources'!$A$159:$A$171,0),MATCH(B$5,'10_Data_Sources'!$B$158:$F$158,0))="","–",INDEX('10_Data_Sources'!$B$159:$F$171,MATCH($A12,'10_Data_Sources'!$A$159:$A$171,0),MATCH(B$5,'10_Data_Sources'!$B$158:$F$158,0))) -> – | C12: =IF(INDEX('10_Data_Sources'!$B$159:$F$171,MATCH($A12,'10_Data_Sources'!$A$159:$A$171,0),MATCH(C$5,'10_Data_Sources'!$B$158:$F$158,0))="","–",INDEX('10_Data_Sources'!$B$159:$F$171,MATCH($A12,'10_Data_Sources'!$A$159:$A$171,0),MATCH(C$5,'10_Data_Sources'!$B$158:$F$158,0))) -> – | D12: =IF(INDEX('10_Data_Sources'!$B$159:$F$171,MATCH($A12,'10_Data_Sources'!$A$159:$A$171,0),MATCH(D$5,'10_Data_Sources'!$B$158:$F$158,0))="","–",INDEX('10_Data_Sources'!$B$159:$F$171,MATCH($A12,'10_Data_Sources'!$A$159:$A$171,0),MATCH(D$5,'10_Data_Sources'!$B$158:$F$158,0))) -> – | E12: =IF(INDEX('10_Data_Sources'!$B$159:$F$171,MATCH($A12,'10_Data_Sources'!$A$159:$A$171,0),MATCH(E$5,'10_Data_Sources'!$B$158:$F$158,0))="","–",INDEX('10_Data_Sources'!$B$159:$F$171,MATCH($A12,'10_Data_Sources'!$A$159:$A$171,0),MATCH(E$5,'10_Data_Sources'!$B$158:$F$158,0))) -> – | F12: =IF(INDEX('10_Data_Sources'!$B$159:$F$171,MATCH($A12,'10_Data_Sources'!$A$159:$A$171,0),MATCH(F$5,'10_Data_Sources'!$B$158:$F$158,0))="","–",INDEX('10_Data_Sources'!$B$159:$F$171,MATCH($A12,'10_Data_Sources'!$A$159:$A$171,0),MATCH(F$5,'10_Data_Sources'!$B$158:$F$158,0))) -> 0.46072954
A13: dso_days | B13: =IF(INDEX('10_Data_Sources'!$B$159:$F$171,MATCH($A13,'10_Data_Sources'!$A$159:$A$171,0),MATCH(B$5,'10_Data_Sources'!$B$158:$F$158,0))="","–",INDEX('10_Data_Sources'!$B$159:$F$171,MATCH($A13,'10_Data_Sources'!$A$159:$A$171,0),MATCH(B$5,'10_Data_Sources'!$B$158:$F$158,0))) -> 0.6695291 | C13: =IF(INDEX('10_Data_Sources'!$B$159:$F$171,MATCH($A13,'10_Data_Sources'!$A$159:$A$171,0),MATCH(C$5,'10_Data_Sources'!$B$158:$F$158,0))="","–",INDEX('10_Data_Sources'!$B$159:$F$171,MATCH($A13,'10_Data_Sources'!$A$159:$A$171,0),MATCH(C$5,'10_Data_Sources'!$B$158:$F$158,0))) -> 0.87571391 | D13: =IF(INDEX('10_Data_Sources'!$B$159:$F$171,MATCH($A13,'10_Data_Sources'!$A$159:$A$171,0),MATCH(D$5,'10_Data_Sources'!$B$158:$F$158,0))="","–",INDEX('10_Data_Sources'!$B$159:$F$171,MATCH($A13,'10_Data_Sources'!$A$159:$A$171,0),MATCH(D$5,'10_Data_Sources'!$B$158:$F$158,0))) -> 0.96949676 | E13: =IF(INDEX('10_Data_Sources'!$B$159:$F$171,MATCH($A13,'10_Data_Sources'!$A$159:$A$171,0),MATCH(E$5,'10_Data_Sources'!$B$158:$F$158,0))="","–",INDEX('10_Data_Sources'!$B$159:$F$171,MATCH($A13,'10_Data_Sources'!$A$159:$A$171,0),MATCH(E$5,'10_Data_Sources'!$B$158:$F$158,0))) -> 0.92182831 | F13: =IF(INDEX('10_Data_Sources'!$B$159:$F$171,MATCH($A13,'10_Data_Sources'!$A$159:$A$171,0),MATCH(F$5,'10_Data_Sources'!$B$158:$F$158,0))="","–",INDEX('10_Data_Sources'!$B$159:$F$171,MATCH($A13,'10_Data_Sources'!$A$159:$A$171,0),MATCH(F$5,'10_Data_Sources'!$B$158:$F$158,0))) -> 1.3751785
A14: dio_days | B14: =IF(INDEX('10_Data_Sources'!$B$159:$F$171,MATCH($A14,'10_Data_Sources'!$A$159:$A$171,0),MATCH(B$5,'10_Data_Sources'!$B$158:$F$158,0))="","–",INDEX('10_Data_Sources'!$B$159:$F$171,MATCH($A14,'10_Data_Sources'!$A$159:$A$171,0),MATCH(B$5,'10_Data_Sources'!$B$158:$F$158,0))) -> 93.430928 | C14: =IF(INDEX('10_Data_Sources'!$B$159:$F$171,MATCH($A14,'10_Data_Sources'!$A$159:$A$171,0),MATCH(C$5,'10_Data_Sources'!$B$158:$F$158,0))="","–",INDEX('10_Data_Sources'!$B$159:$F$171,MATCH($A14,'10_Data_Sources'!$A$159:$A$171,0),MATCH(C$5,'10_Data_Sources'!$B$158:$F$158,0))) -> 97.761214 | D14: =IF(INDEX('10_Data_Sources'!$B$159:$F$171,MATCH($A14,'10_Data_Sources'!$A$159:$A$171,0),MATCH(D$5,'10_Data_Sources'!$B$158:$F$158,0))="","–",INDEX('10_Data_Sources'!$B$159:$F$171,MATCH($A14,'10_Data_Sources'!$A$159:$A$171,0),MATCH(D$5,'10_Data_Sources'!$B$158:$F$158,0))) -> 74.589004 | E14: =IF(INDEX('10_Data_Sources'!$B$159:$F$171,MATCH($A14,'10_Data_Sources'!$A$159:$A$171,0),MATCH(E$5,'10_Data_Sources'!$B$158:$F$158,0))="","–",INDEX('10_Data_Sources'!$B$159:$F$171,MATCH($A14,'10_Data_Sources'!$A$159:$A$171,0),MATCH(E$5,'10_Data_Sources'!$B$158:$F$158,0))) -> 55.462928 | F14: =IF(INDEX('10_Data_Sources'!$B$159:$F$171,MATCH($A14,'10_Data_Sources'!$A$159:$A$171,0),MATCH(F$5,'10_Data_Sources'!$B$158:$F$158,0))="","–",INDEX('10_Data_Sources'!$B$159:$F$171,MATCH($A14,'10_Data_Sources'!$A$159:$A$171,0),MATCH(F$5,'10_Data_Sources'!$B$158:$F$158,0))) -> 40.482999
A15: dpo_days | B15: =IF(INDEX('10_Data_Sources'!$B$159:$F$171,MATCH($A15,'10_Data_Sources'!$A$159:$A$171,0),MATCH(B$5,'10_Data_Sources'!$B$158:$F$158,0))="","–",INDEX('10_Data_Sources'!$B$159:$F$171,MATCH($A15,'10_Data_Sources'!$A$159:$A$171,0),MATCH(B$5,'10_Data_Sources'!$B$158:$F$158,0))) -> 50.548758 | C15: =IF(INDEX('10_Data_Sources'!$B$159:$F$171,MATCH($A15,'10_Data_Sources'!$A$159:$A$171,0),MATCH(C$5,'10_Data_Sources'!$B$158:$F$158,0))="","–",INDEX('10_Data_Sources'!$B$159:$F$171,MATCH($A15,'10_Data_Sources'!$A$159:$A$171,0),MATCH(C$5,'10_Data_Sources'!$B$158:$F$158,0))) -> 29.52233 | D15: =IF(INDEX('10_Data_Sources'!$B$159:$F$171,MATCH($A15,'10_Data_Sources'!$A$159:$A$171,0),MATCH(D$5,'10_Data_Sources'!$B$158:$F$158,0))="","–",INDEX('10_Data_Sources'!$B$159:$F$171,MATCH($A15,'10_Data_Sources'!$A$159:$A$171,0),MATCH(D$5,'10_Data_Sources'!$B$158:$F$158,0))) -> 26.914077 | E15: =IF(INDEX('10_Data_Sources'!$B$159:$F$171,MATCH($A15,'10_Data_Sources'!$A$159:$A$171,0),MATCH(E$5,'10_Data_Sources'!$B$158:$F$158,0))="","–",INDEX('10_Data_Sources'!$B$159:$F$171,MATCH($A15,'10_Data_Sources'!$A$159:$A$171,0),MATCH(E$5,'10_Data_Sources'!$B$158:$F$158,0))) -> 24.919909 | F15: =IF(INDEX('10_Data_Sources'!$B$159:$F$171,MATCH($A15,'10_Data_Sources'!$A$159:$A$171,0),MATCH(F$5,'10_Data_Sources'!$B$158:$F$158,0))="","–",INDEX('10_Data_Sources'!$B$159:$F$171,MATCH($A15,'10_Data_Sources'!$A$159:$A$171,0),MATCH(F$5,'10_Data_Sources'!$B$158:$F$158,0))) -> 29.084423
A16: capex_pct_revenue | B16: =IF(INDEX('10_Data_Sources'!$B$159:$F$171,MATCH($A16,'10_Data_Sources'!$A$159:$A$171,0),MATCH(B$5,'10_Data_Sources'!$B$158:$F$158,0))="","–",INDEX('10_Data_Sources'!$B$159:$F$171,MATCH($A16,'10_Data_Sources'!$A$159:$A$171,0),MATCH(B$5,'10_Data_Sources'!$B$158:$F$158,0))) -> 0.089706323 | C16: =IF(INDEX('10_Data_Sources'!$B$159:$F$171,MATCH($A16,'10_Data_Sources'!$A$159:$A$171,0),MATCH(C$5,'10_Data_Sources'!$B$158:$F$158,0))="","–",INDEX('10_Data_Sources'!$B$159:$F$171,MATCH($A16,'10_Data_Sources'!$A$159:$A$171,0),MATCH(C$5,'10_Data_Sources'!$B$158:$F$158,0))) -> 0.10061828 | D16: =IF(INDEX('10_Data_Sources'!$B$159:$F$171,MATCH($A16,'10_Data_Sources'!$A$159:$A$171,0),MATCH(D$5,'10_Data_Sources'!$B$158:$F$158,0))="","–",INDEX('10_Data_Sources'!$B$159:$F$171,MATCH($A16,'10_Data_Sources'!$A$159:$A$171,0),MATCH(D$5,'10_Data_Sources'!$B$158:$F$158,0))) -> 0.080134077 | E16: =IF(INDEX('10_Data_Sources'!$B$159:$F$171,MATCH($A16,'10_Data_Sources'!$A$159:$A$171,0),MATCH(E$5,'10_Data_Sources'!$B$158:$F$158,0))="","–",INDEX('10_Data_Sources'!$B$159:$F$171,MATCH($A16,'10_Data_Sources'!$A$159:$A$171,0),MATCH(E$5,'10_Data_Sources'!$B$158:$F$158,0))) -> 0.083016666 | F16: =IF(INDEX('10_Data_Sources'!$B$159:$F$171,MATCH($A16,'10_Data_Sources'!$A$159:$A$171,0),MATCH(F$5,'10_Data_Sources'!$B$158:$F$158,0))="","–",INDEX('10_Data_Sources'!$B$159:$F$171,MATCH($A16,'10_Data_Sources'!$A$159:$A$171,0),MATCH(F$5,'10_Data_Sources'!$B$158:$F$158,0))) -> 0.076898286
A17: da_pct_revenue | B17: =IF(INDEX('10_Data_Sources'!$B$159:$F$171,MATCH($A17,'10_Data_Sources'!$A$159:$A$171,0),MATCH(B$5,'10_Data_Sources'!$B$158:$F$158,0))="","–",INDEX('10_Data_Sources'!$B$159:$F$171,MATCH($A17,'10_Data_Sources'!$A$159:$A$171,0),MATCH(B$5,'10_Data_Sources'!$B$158:$F$158,0))) -> 0.04043654 | C17: =IF(INDEX('10_Data_Sources'!$B$159:$F$171,MATCH($A17,'10_Data_Sources'!$A$159:$A$171,0),MATCH(C$5,'10_Data_Sources'!$B$158:$F$158,0))="","–",INDEX('10_Data_Sources'!$B$159:$F$171,MATCH($A17,'10_Data_Sources'!$A$159:$A$171,0),MATCH(C$5,'10_Data_Sources'!$B$158:$F$158,0))) -> 0.053274303 | D17: =IF(INDEX('10_Data_Sources'!$B$159:$F$171,MATCH($A17,'10_Data_Sources'!$A$159:$A$171,0),MATCH(D$5,'10_Data_Sources'!$B$158:$F$158,0))="","–",INDEX('10_Data_Sources'!$B$159:$F$171,MATCH($A17,'10_Data_Sources'!$A$159:$A$171,0),MATCH(D$5,'10_Data_Sources'!$B$158:$F$158,0))) -> 0.057563474 | E17: =IF(INDEX('10_Data_Sources'!$B$159:$F$171,MATCH($A17,'10_Data_Sources'!$A$159:$A$171,0),MATCH(E$5,'10_Data_Sources'!$B$158:$F$158,0))="","–",INDEX('10_Data_Sources'!$B$159:$F$171,MATCH($A17,'10_Data_Sources'!$A$159:$A$171,0),MATCH(E$5,'10_Data_Sources'!$B$158:$F$158,0))) -> 0.059463384 | F17: =IF(INDEX('10_Data_Sources'!$B$159:$F$171,MATCH($A17,'10_Data_Sources'!$A$159:$A$171,0),MATCH(F$5,'10_Data_Sources'!$B$158:$F$158,0))="","–",INDEX('10_Data_Sources'!$B$159:$F$171,MATCH($A17,'10_Data_Sources'!$A$159:$A$171,0),MATCH(F$5,'10_Data_Sources'!$B$158:$F$158,0))) -> 0.057666833
A18: sbc_pct_revenue | B18: =IF(INDEX('10_Data_Sources'!$B$159:$F$171,MATCH($A18,'10_Data_Sources'!$A$159:$A$171,0),MATCH(B$5,'10_Data_Sources'!$B$158:$F$158,0))="","–",INDEX('10_Data_Sources'!$B$159:$F$171,MATCH($A18,'10_Data_Sources'!$A$159:$A$171,0),MATCH(B$5,'10_Data_Sources'!$B$158:$F$158,0))) -> 0.19812943 | C18: =IF(INDEX('10_Data_Sources'!$B$159:$F$171,MATCH($A18,'10_Data_Sources'!$A$159:$A$171,0),MATCH(C$5,'10_Data_Sources'!$B$158:$F$158,0))="","–",INDEX('10_Data_Sources'!$B$159:$F$171,MATCH($A18,'10_Data_Sources'!$A$159:$A$171,0),MATCH(C$5,'10_Data_Sources'!$B$158:$F$158,0))) -> 0.16390241 | D18: =IF(INDEX('10_Data_Sources'!$B$159:$F$171,MATCH($A18,'10_Data_Sources'!$A$159:$A$171,0),MATCH(D$5,'10_Data_Sources'!$B$158:$F$158,0))="","–",INDEX('10_Data_Sources'!$B$159:$F$171,MATCH($A18,'10_Data_Sources'!$A$159:$A$171,0),MATCH(D$5,'10_Data_Sources'!$B$158:$F$158,0))) -> 0.10527424 | E18: =IF(INDEX('10_Data_Sources'!$B$159:$F$171,MATCH($A18,'10_Data_Sources'!$A$159:$A$171,0),MATCH(E$5,'10_Data_Sources'!$B$158:$F$158,0))="","–",INDEX('10_Data_Sources'!$B$159:$F$171,MATCH($A18,'10_Data_Sources'!$A$159:$A$171,0),MATCH(E$5,'10_Data_Sources'!$B$158:$F$158,0))) -> 0.061316064 | F18: =IF(INDEX('10_Data_Sources'!$B$159:$F$171,MATCH($A18,'10_Data_Sources'!$A$159:$A$171,0),MATCH(F$5,'10_Data_Sources'!$B$158:$F$158,0))="","–",INDEX('10_Data_Sources'!$B$159:$F$171,MATCH($A18,'10_Data_Sources'!$A$159:$A$171,0),MATCH(F$5,'10_Data_Sources'!$B$158:$F$158,0))) -> 0.03960982
A20: Section B: Selected Scenario Assumptions
A21: Scenario currently selected: | B21: ='00_Control_Panel'!C4 -> Best
A23: Driver | B23: 2026 | C23: 2027 | D23: 2028 | E23: 2029 | F23: 2030
A24: revenue_growth_pct | B24: =SUMIFS('10_Data_Sources'!$E$5:$E$154, '10_Data_Sources'!$A$5:$A$154, $A24, '10_Data_Sources'!$C$5:$C$154, '00_Control_Panel'!$C$4, '10_Data_Sources'!$D$5:$D$154, B$23) -> 0.15 | C24: =SUMIFS('10_Data_Sources'!$E$5:$E$154, '10_Data_Sources'!$A$5:$A$154, $A24, '10_Data_Sources'!$C$5:$C$154, '00_Control_Panel'!$C$4, '10_Data_Sources'!$D$5:$D$154, C$23) -> 0.14 | D24: =SUMIFS('10_Data_Sources'!$E$5:$E$154, '10_Data_Sources'!$A$5:$A$154, $A24, '10_Data_Sources'!$C$5:$C$154, '00_Control_Panel'!$C$4, '10_Data_Sources'!$D$5:$D$154, D$23) -> 0.13 | E24: =SUMIFS('10_Data_Sources'!$E$5:$E$154, '10_Data_Sources'!$A$5:$A$154, $A24, '10_Data_Sources'!$C$5:$C$154, '00_Control_Panel'!$C$4, '10_Data_Sources'!$D$5:$D$154, E$23) -> 0.12 | F24: =SUMIFS('10_Data_Sources'!$E$5:$E$154, '10_Data_Sources'!$A$5:$A$154, $A24, '10_Data_Sources'!$C$5:$C$154, '00_Control_Panel'!$C$4, '10_Data_Sources'!$D$5:$D$154, F$23) -> 0.11
A25: gross_margin_pct | B25: =SUMIFS('10_Data_Sources'!$E$5:$E$154, '10_Data_Sources'!$A$5:$A$154, $A25, '10_Data_Sources'!$C$5:$C$154, '00_Control_Panel'!$C$4, '10_Data_Sources'!$D$5:$D$154, B$23) -> 0.55 | C25: =SUMIFS('10_Data_Sources'!$E$5:$E$154, '10_Data_Sources'!$A$5:$A$154, $A25, '10_Data_Sources'!$C$5:$C$154, '00_Control_Panel'!$C$4, '10_Data_Sources'!$D$5:$D$154, C$23) -> 0.555 | D25: =SUMIFS('10_Data_Sources'!$E$5:$E$154, '10_Data_Sources'!$A$5:$A$154, $A25, '10_Data_Sources'!$C$5:$C$154, '00_Control_Panel'!$C$4, '10_Data_Sources'!$D$5:$D$154, D$23) -> 0.56 | E25: =SUMIFS('10_Data_Sources'!$E$5:$E$154, '10_Data_Sources'!$A$5:$A$154, $A25, '10_Data_Sources'!$C$5:$C$154, '00_Control_Panel'!$C$4, '10_Data_Sources'!$D$5:$D$154, E$23) -> 0.565 | F25: =SUMIFS('10_Data_Sources'!$E$5:$E$154, '10_Data_Sources'!$A$5:$A$154, $A25, '10_Data_Sources'!$C$5:$C$154, '00_Control_Panel'!$C$4, '10_Data_Sources'!$D$5:$D$154, F$23) -> 0.57
A26: sga_pct_revenue | B26: =SUMIFS('10_Data_Sources'!$E$5:$E$154, '10_Data_Sources'!$A$5:$A$154, $A26, '10_Data_Sources'!$C$5:$C$154, '00_Control_Panel'!$C$4, '10_Data_Sources'!$D$5:$D$154, B$23) -> 0.53 | C26: =SUMIFS('10_Data_Sources'!$E$5:$E$154, '10_Data_Sources'!$A$5:$A$154, $A26, '10_Data_Sources'!$C$5:$C$154, '00_Control_Panel'!$C$4, '10_Data_Sources'!$D$5:$D$154, C$23) -> 0.5075 | D26: =SUMIFS('10_Data_Sources'!$E$5:$E$154, '10_Data_Sources'!$A$5:$A$154, $A26, '10_Data_Sources'!$C$5:$C$154, '00_Control_Panel'!$C$4, '10_Data_Sources'!$D$5:$D$154, D$23) -> 0.485 | E26: =SUMIFS('10_Data_Sources'!$E$5:$E$154, '10_Data_Sources'!$A$5:$A$154, $A26, '10_Data_Sources'!$C$5:$C$154, '00_Control_Panel'!$C$4, '10_Data_Sources'!$D$5:$D$154, E$23) -> 0.4625 | F26: =SUMIFS('10_Data_Sources'!$E$5:$E$154, '10_Data_Sources'!$A$5:$A$154, $A26, '10_Data_Sources'!$C$5:$C$154, '00_Control_Panel'!$C$4, '10_Data_Sources'!$D$5:$D$154, F$23) -> 0.44
A27: effective_tax_rate_pct | B27: =SUMIFS('10_Data_Sources'!$E$5:$E$154, '10_Data_Sources'!$A$5:$A$154, $A27, '10_Data_Sources'!$C$5:$C$154, '00_Control_Panel'!$C$4, '10_Data_Sources'!$D$5:$D$154, B$23) -> 0.05 | C27: =SUMIFS('10_Data_Sources'!$E$5:$E$154, '10_Data_Sources'!$A$5:$A$154, $A27, '10_Data_Sources'!$C$5:$C$154, '00_Control_Panel'!$C$4, '10_Data_Sources'!$D$5:$D$154, C$23) -> 0.0875 | D27: =SUMIFS('10_Data_Sources'!$E$5:$E$154, '10_Data_Sources'!$A$5:$A$154, $A27, '10_Data_Sources'!$C$5:$C$154, '00_Control_Panel'!$C$4, '10_Data_Sources'!$D$5:$D$154, D$23) -> 0.125 | E27: =SUMIFS('10_Data_Sources'!$E$5:$E$154, '10_Data_Sources'!$A$5:$A$154, $A27, '10_Data_Sources'!$C$5:$C$154, '00_Control_Panel'!$C$4, '10_Data_Sources'!$D$5:$D$154, E$23) -> 0.1625 | F27: =SUMIFS('10_Data_Sources'!$E$5:$E$154, '10_Data_Sources'!$A$5:$A$154, $A27, '10_Data_Sources'!$C$5:$C$154, '00_Control_Panel'!$C$4, '10_Data_Sources'!$D$5:$D$154, F$23) -> 0.2
A28: dso_days | B28: =SUMIFS('10_Data_Sources'!$E$5:$E$154, '10_Data_Sources'!$A$5:$A$154, $A28, '10_Data_Sources'!$C$5:$C$154, '00_Control_Panel'!$C$4, '10_Data_Sources'!$D$5:$D$154, B$23) -> 1.2 | C28: =SUMIFS('10_Data_Sources'!$E$5:$E$154, '10_Data_Sources'!$A$5:$A$154, $A28, '10_Data_Sources'!$C$5:$C$154, '00_Control_Panel'!$C$4, '10_Data_Sources'!$D$5:$D$154, C$23) -> 1.2 | D28: =SUMIFS('10_Data_Sources'!$E$5:$E$154, '10_Data_Sources'!$A$5:$A$154, $A28, '10_Data_Sources'!$C$5:$C$154, '00_Control_Panel'!$C$4, '10_Data_Sources'!$D$5:$D$154, D$23) -> 1.2 | E28: =SUMIFS('10_Data_Sources'!$E$5:$E$154, '10_Data_Sources'!$A$5:$A$154, $A28, '10_Data_Sources'!$C$5:$C$154, '00_Control_Panel'!$C$4, '10_Data_Sources'!$D$5:$D$154, E$23) -> 1.2 | F28: =SUMIFS('10_Data_Sources'!$E$5:$E$154, '10_Data_Sources'!$A$5:$A$154, $A28, '10_Data_Sources'!$C$5:$C$154, '00_Control_Panel'!$C$4, '10_Data_Sources'!$D$5:$D$154, F$23) -> 1.2
A29: dio_days | B29: =SUMIFS('10_Data_Sources'!$E$5:$E$154, '10_Data_Sources'!$A$5:$A$154, $A29, '10_Data_Sources'!$C$5:$C$154, '00_Control_Panel'!$C$4, '10_Data_Sources'!$D$5:$D$154, B$23) -> 38 | C29: =SUMIFS('10_Data_Sources'!$E$5:$E$154, '10_Data_Sources'!$A$5:$A$154, $A29, '10_Data_Sources'!$C$5:$C$154, '00_Control_Panel'!$C$4, '10_Data_Sources'!$D$5:$D$154, C$23) -> 35 | D29: =SUMIFS('10_Data_Sources'!$E$5:$E$154, '10_Data_Sources'!$A$5:$A$154, $A29, '10_Data_Sources'!$C$5:$C$154, '00_Control_Panel'!$C$4, '10_Data_Sources'!$D$5:$D$154, D$23) -> 32 | E29: =SUMIFS('10_Data_Sources'!$E$5:$E$154, '10_Data_Sources'!$A$5:$A$154, $A29, '10_Data_Sources'!$C$5:$C$154, '00_Control_Panel'!$C$4, '10_Data_Sources'!$D$5:$D$154, E$23) -> 29 | F29: =SUMIFS('10_Data_Sources'!$E$5:$E$154, '10_Data_Sources'!$A$5:$A$154, $A29, '10_Data_Sources'!$C$5:$C$154, '00_Control_Panel'!$C$4, '10_Data_Sources'!$D$5:$D$154, F$23) -> 26
A30: dpo_days | B30: =SUMIFS('10_Data_Sources'!$E$5:$E$154, '10_Data_Sources'!$A$5:$A$154, $A30, '10_Data_Sources'!$C$5:$C$154, '00_Control_Panel'!$C$4, '10_Data_Sources'!$D$5:$D$154, B$23) -> 30 | C30: =SUMIFS('10_Data_Sources'!$E$5:$E$154, '10_Data_Sources'!$A$5:$A$154, $A30, '10_Data_Sources'!$C$5:$C$154, '00_Control_Panel'!$C$4, '10_Data_Sources'!$D$5:$D$154, C$23) -> 31 | D30: =SUMIFS('10_Data_Sources'!$E$5:$E$154, '10_Data_Sources'!$A$5:$A$154, $A30, '10_Data_Sources'!$C$5:$C$154, '00_Control_Panel'!$C$4, '10_Data_Sources'!$D$5:$D$154, D$23) -> 32 | E30: =SUMIFS('10_Data_Sources'!$E$5:$E$154, '10_Data_Sources'!$A$5:$A$154, $A30, '10_Data_Sources'!$C$5:$C$154, '00_Control_Panel'!$C$4, '10_Data_Sources'!$D$5:$D$154, E$23) -> 33 | F30: =SUMIFS('10_Data_Sources'!$E$5:$E$154, '10_Data_Sources'!$A$5:$A$154, $A30, '10_Data_Sources'!$C$5:$C$154, '00_Control_Panel'!$C$4, '10_Data_Sources'!$D$5:$D$154, F$23) -> 34
A31: capex_pct_revenue | B31: =SUMIFS('10_Data_Sources'!$E$5:$E$154, '10_Data_Sources'!$A$5:$A$154, $A31, '10_Data_Sources'!$C$5:$C$154, '00_Control_Panel'!$C$4, '10_Data_Sources'!$D$5:$D$154, B$23) -> 0.075 | C31: =SUMIFS('10_Data_Sources'!$E$5:$E$154, '10_Data_Sources'!$A$5:$A$154, $A31, '10_Data_Sources'!$C$5:$C$154, '00_Control_Panel'!$C$4, '10_Data_Sources'!$D$5:$D$154, C$23) -> 0.07375 | D31: =SUMIFS('10_Data_Sources'!$E$5:$E$154, '10_Data_Sources'!$A$5:$A$154, $A31, '10_Data_Sources'!$C$5:$C$154, '00_Control_Panel'!$C$4, '10_Data_Sources'!$D$5:$D$154, D$23) -> 0.0725 | E31: =SUMIFS('10_Data_Sources'!$E$5:$E$154, '10_Data_Sources'!$A$5:$A$154, $A31, '10_Data_Sources'!$C$5:$C$154, '00_Control_Panel'!$C$4, '10_Data_Sources'!$D$5:$D$154, E$23) -> 0.07125 | F31: =SUMIFS('10_Data_Sources'!$E$5:$E$154, '10_Data_Sources'!$A$5:$A$154, $A31, '10_Data_Sources'!$C$5:$C$154, '00_Control_Panel'!$C$4, '10_Data_Sources'!$D$5:$D$154, F$23) -> 0.07
A32: da_pct_revenue | B32: =SUMIFS('10_Data_Sources'!$E$5:$E$154, '10_Data_Sources'!$A$5:$A$154, $A32, '10_Data_Sources'!$C$5:$C$154, '00_Control_Panel'!$C$4, '10_Data_Sources'!$D$5:$D$154, B$23) -> 0.056 | C32: =SUMIFS('10_Data_Sources'!$E$5:$E$154, '10_Data_Sources'!$A$5:$A$154, $A32, '10_Data_Sources'!$C$5:$C$154, '00_Control_Panel'!$C$4, '10_Data_Sources'!$D$5:$D$154, C$23) -> 0.0555 | D32: =SUMIFS('10_Data_Sources'!$E$5:$E$154, '10_Data_Sources'!$A$5:$A$154, $A32, '10_Data_Sources'!$C$5:$C$154, '00_Control_Panel'!$C$4, '10_Data_Sources'!$D$5:$D$154, D$23) -> 0.055 | E32: =SUMIFS('10_Data_Sources'!$E$5:$E$154, '10_Data_Sources'!$A$5:$A$154, $A32, '10_Data_Sources'!$C$5:$C$154, '00_Control_Panel'!$C$4, '10_Data_Sources'!$D$5:$D$154, E$23) -> 0.0545 | F32: =SUMIFS('10_Data_Sources'!$E$5:$E$154, '10_Data_Sources'!$A$5:$A$154, $A32, '10_Data_Sources'!$C$5:$C$154, '00_Control_Panel'!$C$4, '10_Data_Sources'!$D$5:$D$154, F$23) -> 0.054
A33: sbc_pct_revenue | B33: =SUMIFS('10_Data_Sources'!$E$5:$E$154, '10_Data_Sources'!$A$5:$A$154, $A33, '10_Data_Sources'!$C$5:$C$154, '00_Control_Panel'!$C$4, '10_Data_Sources'!$D$5:$D$154, B$23) -> 0.032 | C33: =SUMIFS('10_Data_Sources'!$E$5:$E$154, '10_Data_Sources'!$A$5:$A$154, $A33, '10_Data_Sources'!$C$5:$C$154, '00_Control_Panel'!$C$4, '10_Data_Sources'!$D$5:$D$154, C$23) -> 0.0295 | D33: =SUMIFS('10_Data_Sources'!$E$5:$E$154, '10_Data_Sources'!$A$5:$A$154, $A33, '10_Data_Sources'!$C$5:$C$154, '00_Control_Panel'!$C$4, '10_Data_Sources'!$D$5:$D$154, D$23) -> 0.027 | E33: =SUMIFS('10_Data_Sources'!$E$5:$E$154, '10_Data_Sources'!$A$5:$A$154, $A33, '10_Data_Sources'!$C$5:$C$154, '00_Control_Panel'!$C$4, '10_Data_Sources'!$D$5:$D$154, E$23) -> 0.0245 | F33: =SUMIFS('10_Data_Sources'!$E$5:$E$154, '10_Data_Sources'!$A$5:$A$154, $A33, '10_Data_Sources'!$C$5:$C$154, '00_Control_Panel'!$C$4, '10_Data_Sources'!$D$5:$D$154, F$23) -> 0.022

Sheet 02_Historical_IS_BS_CF
A1: Historical Financials (FY2021 - FY2025, $ in thousands)
A3: Income Statement
A4: Line Item | B4: 2021 | C4: =B4+1 -> 2022 | D4: =C4+1 -> 2023 | E4: =D4+1 -> 2024 | F4: =E4+1 -> 2025
A5: Net revenue | B5: 540798 | C5: 598112 | D5: 669765 | E5: 771315 | F5: 871905
A6: Cost of goods sold | B6: 223049 | C6: 257050 | D6: 304541 | E6: 344481 | F6: 401326
A7: Gross profit | B7: =B5-B6 -> 317749 | C7: =C5-C6 -> 341062 | D7: =D5-D6 -> 365224 | E7: =E5-E6 -> 426834 | F7: =F5-F6 -> 470579
A8: Selling, general, and administrative expenses | B8: 461410 | C8: 452265 | D8: 437220 | E8: 456946 | F8: 475915
A9: Operating income (loss) | B9: =B7-B8 -> -143661 | C9: =C7-C8 -> -111203 | D9: =D7-D8 -> -71996 | E9: =E7-E8 -> -30112 | F9: =F7-F8 -> -5336
A10: Interest and other income (loss), net | B10: -347 | C10: 1307 | D10: 9232 | E10: 10597 | F10: 8379
A11: Income (loss) before income taxes | B11: =B9+B10 -> -144008 | C11: =C9+C10 -> -109896 | D11: =D9+D10 -> -62764 | E11: =E9+E10 -> -19515 | F11: =F9+F10 -> 3043
A12: Provision for income taxes | B12: 263 | C12: 497 | D12: 433 | E12: 875 | F12: 1402
A13: Net income (loss) | B13: =B11-B12 -> -144271 | C13: =C11-C12 -> -110393 | D13: =D11-D12 -> -63197 | E13: =E11-E12 -> -20390 | F13: =F11-F12 -> 1641
A16: QC Check: Formula vs. Reported
A17: Gross profit check | B17: =B7-B21 -> 0 | C17: =C7-C21 -> 0 | D17: =D7-D21 -> 0 | E17: =E7-E21 -> 0 | F17: =F7-F21 -> 0
A18: Operating income check | B18: =B9-B22 -> 0 | C18: =C9-C22 -> 0 | D18: =D9-D22 -> 0 | E18: =E9-E22 -> 0 | F18: =F9-F22 -> 0
A19: Net income check | B19: =B13-B23 -> 0 | C19: =C13-C23 -> 0 | D19: =D13-D23 -> 0 | E19: =E13-E23 -> 0 | F19: =F13-F23 -> 0
A21: Reported: Gross profit | B21: 317749 | C21: 341062 | D21: 365224 | E21: 426834 | F21: 470579
A22: Reported: Operating income | B22: -143661 | C22: -111203 | D22: -71996 | E22: -30112 | F22: -5336
A23: Reported: Net income | B23: -144271 | C23: -110393 | D23: -63197 | E23: -20390 | F23: 1641
A26: Balance Sheet
A27: Line Item | B27: 2021 | C27: =B27+1 -> 2022 | D27: =C27+1 -> 2023 | E27: =D27+1 -> 2024 | F27: =E27+1 -> 2025
A28: Cash and cash equivalents | B28: 256416 | C28: 208585 | D28: 216894 | E28: 254161 | F28: 286358
A29: Accounts receivable, net | B29: 992 | C29: 1435 | D29: 1779 | E29: 1948 | F29: 3285
A30: Inventory | B30: 57095 | C30: 68848 | D30: 62234 | E30: 52345 | F30: 44512
A31: Prepaid expenses and other current assets | B31: 13477 | C31: 15700 | D31: 17712 | E31: 17592 | F31: 18283
A32: Total current assets | B32: =SUM(B28:B31) -> 327980 | C32: =SUM(C28:C31) -> 294568 | D32: =SUM(D28:D31) -> 298619 | E32: =SUM(E28:E31) -> 326046 | F32: =SUM(F28:F31) -> 352438
A33: Property and equipment, net | B33: 112195 | C33: 138628 | D33: 152332 | E33: 170464 | F33: 187448
A34: Right-of-use lease assets | B34: 0 | C34: 127014 | D34: 122305 | E34: 171284 | F34: 170805
A35: Other assets | B35: 471 | C35: 8497 | D35: 7056 | E35: 8696 | F35: 10228
A36: Total assets | B36: =B32+B33+B34+B35 -> 440646 | C36: =C32+C33+C34+C35 -> 568707 | D36: =D32+D33+D34+D35 -> 580312 | E36: =E32+E33+E34+E35 -> 676490 | F36: =F32+F33+F34+F35 -> 720919
A37: Accounts payable | B37: 30890 | C37: 20791 | D37: 22456 | E37: 23519 | F37: 31979
A38: Accrued expenses | B38: 60840 | C38: 58222 | D38: 46320 | E38: 51609 | F38: 49225
A39: Deferred revenue | B39: 22073 | C39: 25628 | D39: 31617 | E39: 32358 | F39: 33869
A40: Current lease liabilities | B40: 0 | C40: 22546 | D40: 24286 | E40: 20235 | F40: 31399
A41: Other current liabilities | B41: 4301 | C41: 2370 | D41: 2411 | E41: 2633 | F41: 3658
A42: Total current liabilities | B42: =SUM(B37:B41) -> 118104 | C42: =SUM(C37:C41) -> 129557 | D42: =SUM(D37:D41) -> 127090 | E42: =SUM(E37:E41) -> 130354 | F42: =SUM(F37:F41) -> 150130
A43: Non-current lease liabilities | B43: 0 | C43: 150832 | D43: 150171 | E43: 205120 | F43: 201749
A44: Deferred rent | B44: 36544 | C44: 0 | D44: 0 | E44: 0 | F44: 0
A45: Other liabilities | B45: 0 | C45: 1672 | D45: 1264 | E45: 943 | F45: 1310
A46: Total liabilities | B46: =B42+B43+B44+B45 -> 154648 | C46: =C42+C43+C44+C45 -> 282061 | D46: =D42+D43+D44+D45 -> 278525 | E46: =E42+E43+E44+E45 -> 336417 | F46: =F42+F43+F44+F45 -> 353189
...

Sheet 03_Forecast_IS
A1: Forecast Income Statement (FY2026 - FY2030, $ in thousands)
A3: Scenario: | B3: ='00_Control_Panel'!C4 -> Best
A5: Line Item | B5: 2026 | C5: =B5+1 -> 2027 | D5: =C5+1 -> 2028 | E5: =D5+1 -> 2029 | F5: =E5+1 -> 2030
A6: Net revenue | B6: ='02_Historical_IS_BS_CF'!F5*(1+'01_Assumptions'!B24) -> 1002690.7 | C6: =B6*(1+'01_Assumptions'!C24) -> 1143067.5 | D6: =C6*(1+'01_Assumptions'!D24) -> 1291666.2 | E6: =D6*(1+'01_Assumptions'!E24) -> 1446666.2 | F6: =E6*(1+'01_Assumptions'!F24) -> 1605799.4
A7: Cost of goods sold | B7: =B6*(1-'01_Assumptions'!B25) -> 451210.84 | C7: =C6*(1-'01_Assumptions'!C25) -> 508665.02 | D7: =D6*(1-'01_Assumptions'!D25) -> 568333.14 | E7: =E6*(1-'01_Assumptions'!E25) -> 629299.78 | F7: =F6*(1-'01_Assumptions'!F25) -> 690493.76
A8: Gross profit | B8: =B6-B7 -> 551479.91 | C8: =C6-C7 -> 634402.44 | D8: =D6-D7 -> 723333.09 | E8: =E6-E7 -> 817366.39 | F8: =F6-F7 -> 915305.69
A9: Selling, general, and administrative expenses | B9: =B6*'01_Assumptions'!B26 -> 531426.1 | C9: =C6*'01_Assumptions'!C26 -> 580106.73 | D9: =D6*'01_Assumptions'!D26 -> 626458.12 | E9: =E6*'01_Assumptions'!E26 -> 669083.1 | F9: =F6*'01_Assumptions'!F26 -> 706551.76
A10: Operating income (loss) | B10: =B8-B9 -> 20053.815 | C10: =C8-C9 -> 54295.704 | D10: =D8-D9 -> 96874.967 | E10: =E8-E9 -> 148283.28 | F10: =F8-F9 -> 208753.93
A11: Interest and other income (loss), net | B11: ='02_Historical_IS_BS_CF'!$F$10 -> 8379 | C11: ='02_Historical_IS_BS_CF'!$F$10 -> 8379 | D11: ='02_Historical_IS_BS_CF'!$F$10 -> 8379 | E11: ='02_Historical_IS_BS_CF'!$F$10 -> 8379 | F11: ='02_Historical_IS_BS_CF'!$F$10 -> 8379
A12: Income (loss) before income taxes | B12: =B10+B11 -> 28432.815 | C12: =C10+C11 -> 62674.704 | D12: =D10+D11 -> 105253.97 | E12: =E10+E11 -> 156662.28 | F12: =F10+F11 -> 217132.93
A13: Provision for income taxes | B13: =IF(B12<=0,0,B12*'01_Assumptions'!B27) -> 1421.6408 | C13: =IF(C12<=0,0,C12*'01_Assumptions'!C27) -> 5484.0366 | D13: =IF(D12<=0,0,D12*'01_Assumptions'!D27) -> 13156.746 | E13: =IF(E12<=0,0,E12*'01_Assumptions'!E27) -> 25457.621 | F13: =IF(F12<=0,0,F12*'01_Assumptions'!F27) -> 43426.586
A14: Net income (loss) | B14: =B12-B13 -> 27011.174 | C14: =C12-C13 -> 57190.668 | D14: =D12-D13 -> 92097.221 | E14: =E12-E13 -> 131204.66 | F14: =F12-F13 -> 173706.34

Sheet 04_Forecast_BS
A1: Forecast Balance Sheet (FY2026 - FY2030, $ in thousands)
A3: Scenario: | B3: ='00_Control_Panel'!C4 -> Best
A5: Assets
A6: Line Item | B6: 2026 | C6: =B6+1 -> 2027 | D6: =C6+1 -> 2028 | E6: =D6+1 -> 2029 | F6: =E6+1 -> 2030
A7: Cash and cash equivalents | B7: ='05_Forecast_CF'!B20 -> 329036.08 | C7: ='05_Forecast_CF'!C20 -> 402939.89 | D7: ='05_Forecast_CF'!D20 -> 512393.81 | E7: ='05_Forecast_CF'!E20 -> 661196.98 | F7: ='05_Forecast_CF'!F20 -> 852252.61
A8: Accounts receivable, net | B8: ='06_Supporting_Schedules'!B7 -> 3296.5175 | C8: ='06_Supporting_Schedules'!C7 -> 3758.03 | D8: ='06_Supporting_Schedules'!D7 -> 4246.5739 | E8: ='06_Supporting_Schedules'!E7 -> 4756.1628 | F8: ='06_Supporting_Schedules'!F7 -> 5279.3407
A9: Inventory | B9: ='06_Supporting_Schedules'!B8 -> 46975.375 | C9: ='06_Supporting_Schedules'!C8 -> 48776.098 | D9: ='06_Supporting_Schedules'!D8 -> 49826.467 | E9: ='06_Supporting_Schedules'!E8 -> 49999.161 | F9: ='06_Supporting_Schedules'!F8 -> 49185.857
A10: Prepaid expenses and other current assets | B10: ='02_Historical_IS_BS_CF'!$F$31 -> 18283 | C10: ='02_Historical_IS_BS_CF'!$F$31 -> 18283 | D10: ='02_Historical_IS_BS_CF'!$F$31 -> 18283 | E10: ='02_Historical_IS_BS_CF'!$F$31 -> 18283 | F10: ='02_Historical_IS_BS_CF'!$F$31 -> 18283
A11: Total current assets | B11: =B7+B8+B9+B10 -> 397590.98 | C11: =C7+C8+C9+C10 -> 473757.02 | D11: =D7+D8+D9+D10 -> 584749.85 | E11: =E7+E8+E9+E10 -> 734235.3 | F11: =F7+F8+F9+F10 -> 925000.81
A12: Property and equipment, net | B12: ='06_Supporting_Schedules'!B17 -> 206499.12 | C12: ='06_Supporting_Schedules'!C17 -> 227360.11 | D12: ='06_Supporting_Schedules'!D17 -> 249964.26 | E12: ='06_Supporting_Schedules'!E17 -> 274195.92 | F12: ='06_Supporting_Schedules'!F17 -> 299888.71
A13: Right-of-use lease assets | B13: ='02_Historical_IS_BS_CF'!$F$34 -> 170805 | C13: ='02_Historical_IS_BS_CF'!$F$34 -> 170805 | D13: ='02_Historical_IS_BS_CF'!$F$34 -> 170805 | E13: ='02_Historical_IS_BS_CF'!$F$34 -> 170805 | F13: ='02_Historical_IS_BS_CF'!$F$34 -> 170805
A14: Other assets | B14: ='02_Historical_IS_BS_CF'!$F$35 -> 10228 | C14: ='02_Historical_IS_BS_CF'!$F$35 -> 10228 | D14: ='02_Historical_IS_BS_CF'!$F$35 -> 10228 | E14: ='02_Historical_IS_BS_CF'!$F$35 -> 10228 | F14: ='02_Historical_IS_BS_CF'!$F$35 -> 10228
A15: Total assets | B15: =B11+B12+B13+B14 -> 785123.1 | C15: =C11+C12+C13+C14 -> 882150.12 | D15: =D11+D12+D13+D14 -> 1015747.1 | E15: =E11+E12+E13+E14 -> 1189464.2 | F15: =F11+F12+F13+F14 -> 1405922.5
A17: Liabilities and Equity
A18: Line Item | B18: 2026 | C18: =B18+1 -> 2027 | D18: =C18+1 -> 2028 | E18: =D18+1 -> 2029 | F18: =E18+1 -> 2030
A19: Accounts payable | B19: ='06_Supporting_Schedules'!B9 -> 37085.822 | C19: ='06_Supporting_Schedules'!C9 -> 43201.686 | D19: ='06_Supporting_Schedules'!D9 -> 49826.467 | E19: ='06_Supporting_Schedules'!E9 -> 56895.597 | F19: ='06_Supporting_Schedules'!F9 -> 64319.967
A20: Accrued expenses | B20: ='02_Historical_IS_BS_CF'!$F$38 -> 49225 | C20: ='02_Historical_IS_BS_CF'!$F$38 -> 49225 | D20: ='02_Historical_IS_BS_CF'!$F$38 -> 49225 | E20: ='02_Historical_IS_BS_CF'!$F$38 -> 49225 | F20: ='02_Historical_IS_BS_CF'!$F$38 -> 49225
A21: Deferred revenue | B21: ='02_Historical_IS_BS_CF'!$F$39 -> 33869 | C21: ='02_Historical_IS_BS_CF'!$F$39 -> 33869 | D21: ='02_Historical_IS_BS_CF'!$F$39 -> 33869 | E21: ='02_Historical_IS_BS_CF'!$F$39 -> 33869 | F21: ='02_Historical_IS_BS_CF'!$F$39 -> 33869
A22: Current lease liabilities | B22: ='02_Historical_IS_BS_CF'!$F$40 -> 31399 | C22: ='02_Historical_IS_BS_CF'!$F$40 -> 31399 | D22: ='02_Historical_IS_BS_CF'!$F$40 -> 31399 | E22: ='02_Historical_IS_BS_CF'!$F$40 -> 31399 | F22: ='02_Historical_IS_BS_CF'!$F$40 -> 31399
A23: Other current liabilities | B23: ='02_Historical_IS_BS_CF'!$F$41 -> 3658 | C23: ='02_Historical_IS_BS_CF'!$F$41 -> 3658 | D23: ='02_Historical_IS_BS_CF'!$F$41 -> 3658 | E23: ='02_Historical_IS_BS_CF'!$F$41 -> 3658 | F23: ='02_Historical_IS_BS_CF'!$F$41 -> 3658
A24: Total current liabilities | B24: =SUM(B19:B23) -> 155236.82 | C24: =SUM(C19:C23) -> 161352.69 | D24: =SUM(D19:D23) -> 167977.47 | E24: =SUM(E19:E23) -> 175046.6 | F24: =SUM(F19:F23) -> 182470.97
A25: Non-current lease liabilities | B25: ='02_Historical_IS_BS_CF'!$F$43 -> 201749 | C25: ='02_Historical_IS_BS_CF'!$F$43 -> 201749 | D25: ='02_Historical_IS_BS_CF'!$F$43 -> 201749 | E25: ='02_Historical_IS_BS_CF'!$F$43 -> 201749 | F25: ='02_Historical_IS_BS_CF'!$F$43 -> 201749
A26: Deferred rent | B26: ='02_Historical_IS_BS_CF'!$F$44 -> 0 | C26: ='02_Historical_IS_BS_CF'!$F$44 -> 0 | D26: ='02_Historical_IS_BS_CF'!$F$44 -> 0 | E26: ='02_Historical_IS_BS_CF'!$F$44 -> 0 | F26: ='02_Historical_IS_BS_CF'!$F$44 -> 0
A27: Other liabilities | B27: ='02_Historical_IS_BS_CF'!$F$45 -> 1310 | C27: ='02_Historical_IS_BS_CF'!$F$45 -> 1310 | D27: ='02_Historical_IS_BS_CF'!$F$45 -> 1310 | E27: ='02_Historical_IS_BS_CF'!$F$45 -> 1310 | F27: ='02_Historical_IS_BS_CF'!$F$45 -> 1310
A28: Total liabilities | B28: =B24+B25+B26+B27 -> 358295.82 | C28: =C24+C25+C26+C27 -> 364411.69 | D28: =D24+D25+D26+D27 -> 371036.47 | E28: =E24+E25+E26+E27 -> 378105.6 | F28: =F24+F25+F26+F27 -> 385529.97
A29: Common Stock | B29: ='02_Historical_IS_BS_CF'!$F$47 -> 12 | C29: ='02_Historical_IS_BS_CF'!$F$47 -> 12 | D29: ='02_Historical_IS_BS_CF'!$F$47 -> 12 | E29: ='02_Historical_IS_BS_CF'!$F$47 -> 12 | F29: ='02_Historical_IS_BS_CF'!$F$47 -> 12
A30: Additional paid-in capital | B30: =('02_Historical_IS_BS_CF'!$F$48)+'05_Forecast_CF'!B9 -> 1086865.1 | C30: =B30+'05_Forecast_CF'!C9 -> 1120585.6 | D30: =C30+'05_Forecast_CF'!D9 -> 1155460.6 | E30: =D30+'05_Forecast_CF'!E9 -> 1190903.9 | F30: =E30+'05_Forecast_CF'!F9 -> 1226231.5
A31: Accumulated deficit | B31: ='02_Historical_IS_BS_CF'!F49+'03_Forecast_IS'!B14 -> -658568.83 | C31: =B31+'03_Forecast_IS'!C14 -> -601378.16 | D31: =C31+'03_Forecast_IS'!D14 -> -509280.94 | E31: =D31+'03_Forecast_IS'!E14 -> -378076.28 | F31: =E31+'03_Forecast_IS'!F14 -> -204369.93
A32: Accumulated other comprehensive income | B32: ='02_Historical_IS_BS_CF'!$F$50 -> -1481 | C32: ='02_Historical_IS_BS_CF'!$F$50 -> -1481 | D32: ='02_Historical_IS_BS_CF'!$F$50 -> -1481 | E32: ='02_Historical_IS_BS_CF'!$F$50 -> -1481 | F32: ='02_Historical_IS_BS_CF'!$F$50 -> -1481
A33: Total stockholders' equity | B33: =SUM(B29:B32) -> 426827.28 | C33: =SUM(C29:C32) -> 517738.44 | D33: =SUM(D29:D32) -> 644710.64 | E33: =SUM(E29:E32) -> 811358.63 | F33: =SUM(F29:F32) -> 1020392.6
A34: Total liabilities and stockholders' equity | B34: =B28+B33 -> 785123.1 | C34: =C28+C33 -> 882150.12 | D34: =D28+D33 -> 1015747.1 | E34: =E28+E33 -> 1189464.2 | F34: =F28+F33 -> 1405922.5
A36: GOLDEN TIE: Assets = Liab + Equity | B36: =B15-B34 -> 0 | C36: =C15-C34 -> 0 | D36: =D15-D34 -> 0 | E36: =E15-E34 -> 0 | F36: =F15-F34 -> 0

Sheet 05_Forecast_CF
A1: Forecast Cash Flow Statement (FY2026 - FY2030, $ in thousands)
A3: Scenario: | B3: ='00_Control_Panel'!C4 -> Best
A6: Line Item | B6: 2026 | C6: =B6+1 -> 2027 | D6: =C6+1 -> 2028 | E6: =D6+1 -> 2029 | F6: =E6+1 -> 2030
A7: Net income (loss) | B7: ='03_Forecast_IS'!B14 -> 27011.174 | C7: ='03_Forecast_IS'!C14 -> 57190.668 | D7: ='03_Forecast_IS'!D14 -> 92097.221 | E7: ='03_Forecast_IS'!E14 -> 131204.66 | F7: ='03_Forecast_IS'!F14 -> 173706.34
A8: Depreciation and amortization | B8: ='06_Supporting_Schedules'!B16 -> 56150.682 | C8: ='06_Supporting_Schedules'!C16 -> 63440.244 | D8: ='06_Supporting_Schedules'!D16 -> 71041.642 | E8: ='06_Supporting_Schedules'!E16 -> 78843.306 | F8: ='06_Supporting_Schedules'!F16 -> 86713.17
A9: Stock-based compensation | B9: ='03_Forecast_IS'!B6*'01_Assumptions'!B33 -> 32086.104 | C9: ='03_Forecast_IS'!C6*'01_Assumptions'!C33 -> 33720.49 | D9: ='03_Forecast_IS'!D6*'01_Assumptions'!D33 -> 34874.988 | E9: ='03_Forecast_IS'!E6*'01_Assumptions'!E33 -> 35443.321 | F9: ='03_Forecast_IS'!F6*'01_Assumptions'!F33 -> 35327.588
A10: Change in accounts receivable | B10: =-('04_Forecast_BS'!B8-'02_Historical_IS_BS_CF'!F29) -> -11.517534 | C10: =-('04_Forecast_BS'!C8-'04_Forecast_BS'!B8) -> -461.51245 | D10: =-('04_Forecast_BS'!D8-'04_Forecast_BS'!C8) -> -488.5439 | E10: =-('04_Forecast_BS'!E8-'04_Forecast_BS'!D8) -> -509.58887 | F10: =-('04_Forecast_BS'!F8-'04_Forecast_BS'!E8) -> -523.1779
A11: Change in inventory | B11: =-('04_Forecast_BS'!B9-'02_Historical_IS_BS_CF'!F30) -> -2463.3749 | C11: =-('04_Forecast_BS'!C9-'04_Forecast_BS'!B9) -> -1800.7227 | D11: =-('04_Forecast_BS'!D9-'04_Forecast_BS'!C9) -> -1050.3694 | E11: =-('04_Forecast_BS'!E9-'04_Forecast_BS'!D9) -> -172.694 | F11: =-('04_Forecast_BS'!F9-'04_Forecast_BS'!E9) -> 813.30383
A12: Change in accounts payable | B12: ='04_Forecast_BS'!B19-'02_Historical_IS_BS_CF'!F37 -> 5106.8223 | C12: ='04_Forecast_BS'!C19-'04_Forecast_BS'!B19 -> 6115.8642 | D12: ='04_Forecast_BS'!D19-'04_Forecast_BS'!C19 -> 6624.7805 | E12: ='04_Forecast_BS'!E19-'04_Forecast_BS'!D19 -> 7069.13 | F12: ='04_Forecast_BS'!F19-'04_Forecast_BS'!E19 -> 7424.3701
A13: Net cash provided by operating activities | B13: =SUM(B7:B12) -> 117879.89 | C13: =SUM(C7:C12) -> 158205.03 | D13: =SUM(D7:D12) -> 203099.72 | E13: =SUM(E7:E12) -> 251878.14 | F13: =SUM(F7:F12) -> 303461.6
A14: Capital expenditures | B14: =-'06_Supporting_Schedules'!B15 -> -75201.806 | C14: =-'06_Supporting_Schedules'!C15 -> -84301.225 | D14: =-'06_Supporting_Schedules'!D15 -> -93645.801 | E14: =-'06_Supporting_Schedules'!E15 -> -103074.96 | F14: =-'06_Supporting_Schedules'!F15 -> -112405.96
A15: Net cash used in investing activities | B15: =B14 -> -75201.806 | C15: =C14 -> -84301.225 | D15: =D14 -> -93645.801 | E15: =E14 -> -103074.96 | F15: =F14 -> -112405.96
A16: Net cash provided by (used in) financing activities | B16: 0 | C16: 0 | D16: 0 | E16: 0 | F16: 0 | H16: No new financing modeled - WRBY carries no debt in the historical data
A17: Net increase (decrease) in cash | B17: =B13+B15+B16 -> 42678.084 | C17: =C13+C15+C16 -> 73903.805 | D17: =D13+D15+D16 -> 109453.92 | E17: =E13+E15+E16 -> 148803.17 | F17: =F13+F15+F16 -> 191055.64
A18: Cash, beginning of year | B18: ='02_Historical_IS_BS_CF'!F28 -> 286358 | C18: =B20 -> 329036.08 | D18: =C20 -> 402939.89 | E18: =D20 -> 512393.81 | F18: =E20 -> 661196.98
A20: Cash, end of year | B20: =B17+B18 -> 329036.08 | C20: =C17+C18 -> 402939.89 | D20: =D17+D18 -> 512393.81 | E20: =E17+E18 -> 661196.98 | F20: =F17+F18 -> 852252.61

Sheet 06_Supporting_Schedules
A1: Supporting Schedules (FY2026–FY2030, $ in thousands)
A3: Scenario: | B3: ='00_Control_Panel'!C4 -> Best
A5: Working Capital Schedule
A6: Line Item | B6: 2026 | C6: =B6+1 -> 2027 | D6: =C6+1 -> 2028 | E6: =D6+1 -> 2029 | F6: =E6+1 -> 2030
A7: Accounts receivable, net | B7: ='03_Forecast_IS'!B6/365 * '01_Assumptions'!B28 -> 3296.5175 | C7: ='03_Forecast_IS'!C6/365 * '01_Assumptions'!C28 -> 3758.03 | D7: ='03_Forecast_IS'!D6/365 * '01_Assumptions'!D28 -> 4246.5739 | E7: ='03_Forecast_IS'!E6/365 * '01_Assumptions'!E28 -> 4756.1628 | F7: ='03_Forecast_IS'!F6/365 * '01_Assumptions'!F28 -> 5279.3407
A8: Inventory | B8: ='03_Forecast_IS'!B7/365 * '01_Assumptions'!B29 -> 46975.375 | C8: ='03_Forecast_IS'!C7/365 * '01_Assumptions'!C29 -> 48776.098 | D8: ='03_Forecast_IS'!D7/365 * '01_Assumptions'!D29 -> 49826.467 | E8: ='03_Forecast_IS'!E7/365 * '01_Assumptions'!E29 -> 49999.161 | F8: ='03_Forecast_IS'!F7/365 * '01_Assumptions'!F29 -> 49185.857
A9: Accounts payable | B9: ='03_Forecast_IS'!B7/365 * '01_Assumptions'!B30 -> 37085.822 | C9: ='03_Forecast_IS'!C7/365 * '01_Assumptions'!C30 -> 43201.686 | D9: ='03_Forecast_IS'!D7/365 * '01_Assumptions'!D30 -> 49826.467 | E9: ='03_Forecast_IS'!E7/365 * '01_Assumptions'!E30 -> 56895.597 | F9: ='03_Forecast_IS'!F7/365 * '01_Assumptions'!F30 -> 64319.967
A12: PP&E Roll-Forward
A13: Line Item | B13: 2026 | C13: =B13+1 -> 2027 | D13: =C13+1 -> 2028 | E13: =D13+1 -> 2029 | F13: =E13+1 -> 2030
A14: Beginning PP&E, net | B14: ='02_Historical_IS_BS_CF'!F33 -> 187448 | C14: =B17 -> 206499.12 | D14: =C17 -> 227360.11 | E14: =D17 -> 249964.26 | F14: =E17 -> 274195.92
A15: Capital expenditures (capex) | B15: ='01_Assumptions'!B31*'03_Forecast_IS'!B6 -> 75201.806 | C15: ='01_Assumptions'!C31*'03_Forecast_IS'!C6 -> 84301.225 | D15: ='01_Assumptions'!D31*'03_Forecast_IS'!D6 -> 93645.801 | E15: ='01_Assumptions'!E31*'03_Forecast_IS'!E6 -> 103074.96 | F15: ='01_Assumptions'!F31*'03_Forecast_IS'!F6 -> 112405.96
A16: Depreciation and amortization | B16: ='03_Forecast_IS'!B6*'01_Assumptions'!B32 -> 56150.682 | C16: ='03_Forecast_IS'!C6*'01_Assumptions'!C32 -> 63440.244 | D16: ='03_Forecast_IS'!D6*'01_Assumptions'!D32 -> 71041.642 | E16: ='03_Forecast_IS'!E6*'01_Assumptions'!E32 -> 78843.306 | F16: ='03_Forecast_IS'!F6*'01_Assumptions'!F32 -> 86713.17
A17: Ending PP&E, net | B17: =B14+B15-B16 -> 206499.12 | C17: =C14+C15-C16 -> 227360.11 | D17: =D14+D15-D16 -> 249964.26 | E17: =E14+E15-E16 -> 274195.92 | F17: =F14+F15-F16 -> 299888.71

Sheet 07_Validation
A1: Model Validation Dashboard
A2: All checks should read TRUE / 0. Any FALSE or nonzero value indicates a broken link or formula error.
A4: Scenario: | B4: ='00_Control_Panel'!C4 -> Best
A6: Check | B6: 2026 | C6: =B6+1 -> 2027 | D6: =C6+1 -> 2028 | E6: =D6+1 -> 2029 | F6: =E6+1 -> 2030
A7: Balance Sheet balances | B7: ='04_Forecast_BS'!B15-'04_Forecast_BS'!B34 -> 0 | C7: ='04_Forecast_BS'!C15-'04_Forecast_BS'!C34 -> 0 | D7: ='04_Forecast_BS'!D15-'04_Forecast_BS'!D34 -> 0 | E7: ='04_Forecast_BS'!E15-'04_Forecast_BS'!E34 -> 0 | F7: ='04_Forecast_BS'!F15-'04_Forecast_BS'!F34 -> 0
A8: Cash Flow ties to Balance Sheet cash | B8: ='05_Forecast_CF'!B20-'04_Forecast_BS'!B7 -> 0 | C8: ='05_Forecast_CF'!C20-'04_Forecast_BS'!C7 -> 0 | D8: ='05_Forecast_CF'!D20-'04_Forecast_BS'!D7 -> 0 | E8: ='05_Forecast_CF'!E20-'04_Forecast_BS'!E7 -> 0 | F8: ='05_Forecast_CF'!F20-'04_Forecast_BS'!F7 -> 0
B9: 2021 | C9: =B9+1 -> 2022 | D9: =C9+1 -> 2023 | E9: =D9+1 -> 2024 | F9: =E9+1 -> 2025
A10: Historical Balance Sheet ties | B10: ='02_Historical_IS_BS_CF'!B36-'02_Historical_IS_BS_CF'!B52 -> 11 | C10: ='02_Historical_IS_BS_CF'!C36-'02_Historical_IS_BS_CF'!C52 -> 0 | D10: ='02_Historical_IS_BS_CF'!D36-'02_Historical_IS_BS_CF'!D52 -> 0 | E10: ='02_Historical_IS_BS_CF'!E36-'02_Historical_IS_BS_CF'!E52 -> 0 | F10: ='02_Historical_IS_BS_CF'!F36-'02_Historical_IS_BS_CF'!F52 -> 0
A11: Historical Cash Flow ties to Balance Sheet cash | B11: ='02_Historical_IS_BS_CF'!B95-'02_Historical_IS_BS_CF'!B28 -> 0 | C11: ='02_Historical_IS_BS_CF'!C95-'02_Historical_IS_BS_CF'!C28 -> 0 | D11: ='02_Historical_IS_BS_CF'!D95-'02_Historical_IS_BS_CF'!D28 -> 0 | E11: ='02_Historical_IS_BS_CF'!E95-'02_Historical_IS_BS_CF'!E28 -> 2 | F11: ='02_Historical_IS_BS_CF'!F95-'02_Historical_IS_BS_CF'!F28 -> 2
A12: Scenario validity check | B12: ='00_Control_Panel'!D4 -> ✓ Valid
A14: Overall model status: | B14: =IF(AND(ABS(B7)<=3,ABS(B8)<=3),"✓ Model integrity confirmed","⚠ Review required") -> ✓ Model integrity confirmed | C14: =IF(AND(ABS(C7)<=3,ABS(C8)<=3),"✓ Model integrity confirmed","⚠ Review required") -> ✓ Model integrity confirmed | D14: =IF(AND(ABS(D7)<=3,ABS(D8)<=3),"✓ Model integrity confirmed","⚠ Review required") -> ✓ Model integrity confirmed | E14: =IF(AND(ABS(E7)<=3,ABS(E8)<=3),"✓ Model integrity confirmed","⚠ Review required") -> ✓ Model integrity confirmed | F14: =IF(AND(ABS(F7)<=3,ABS(F8)<=3),"✓ Model integrity confirmed","⚠ Review required") -> ✓ Model integrity confirmed

Sheet 08_Scenario_Planner
A1: Scenario Comparison - Base vs. Best vs. Worst
A2: Independent of Control Panel toggle - shows all three scenarios at once.
A4: BASE CASE
A5: Revenue growth % | B5: =SUMIFS('10_Data_Sources'!$E$5:$E$154,'10_Data_Sources'!$A$5:$A$154,"revenue_growth_pct",'10_Data_Sources'!$C$5:$C$154,"base",'10_Data_Sources'!$D$5:$D$154,B$13) -> 0.13 | C5: =SUMIFS('10_Data_Sources'!$E$5:$E$154,'10_Data_Sources'!$A$5:$A$154,"revenue_growth_pct",'10_Data_Sources'!$C$5:$C$154,"base",'10_Data_Sources'!$D$5:$D$154,C$13) -> 0.115 | D5: =SUMIFS('10_Data_Sources'!$E$5:$E$154,'10_Data_Sources'!$A$5:$A$154,"revenue_growth_pct",'10_Data_Sources'!$C$5:$C$154,"base",'10_Data_Sources'!$D$5:$D$154,D$13) -> 0.1 | E5: =SUMIFS('10_Data_Sources'!$E$5:$E$154,'10_Data_Sources'!$A$5:$A$154,"revenue_growth_pct",'10_Data_Sources'!$C$5:$C$154,"base",'10_Data_Sources'!$D$5:$D$154,E$13) -> 0.085 | F5: =SUMIFS('10_Data_Sources'!$E$5:$E$154,'10_Data_Sources'!$A$5:$A$154,"revenue_growth_pct",'10_Data_Sources'!$C$5:$C$154,"base",'10_Data_Sources'!$D$5:$D$154,F$13) -> 0.07
A6: Gross margin % | B6: =SUMIFS('10_Data_Sources'!$E$5:$E$154,'10_Data_Sources'!$A$5:$A$154,"gross_margin_pct",'10_Data_Sources'!$C$5:$C$154,"base",'10_Data_Sources'!$D$5:$D$154,B$13) -> 0.545 | C6: =SUMIFS('10_Data_Sources'!$E$5:$E$154,'10_Data_Sources'!$A$5:$A$154,"gross_margin_pct",'10_Data_Sources'!$C$5:$C$154,"base",'10_Data_Sources'!$D$5:$D$154,C$13) -> 0.54625 | D6: =SUMIFS('10_Data_Sources'!$E$5:$E$154,'10_Data_Sources'!$A$5:$A$154,"gross_margin_pct",'10_Data_Sources'!$C$5:$C$154,"base",'10_Data_Sources'!$D$5:$D$154,D$13) -> 0.5475 | E6: =SUMIFS('10_Data_Sources'!$E$5:$E$154,'10_Data_Sources'!$A$5:$A$154,"gross_margin_pct",'10_Data_Sources'!$C$5:$C$154,"base",'10_Data_Sources'!$D$5:$D$154,E$13) -> 0.54875 | F6: =SUMIFS('10_Data_Sources'!$E$5:$E$154,'10_Data_Sources'!$A$5:$A$154,"gross_margin_pct",'10_Data_Sources'!$C$5:$C$154,"base",'10_Data_Sources'!$D$5:$D$154,F$13) -> 0.55
A7: SG&A % of revenue | B7: =SUMIFS('10_Data_Sources'!$E$5:$E$154,'10_Data_Sources'!$A$5:$A$154,"sga_pct_revenue",'10_Data_Sources'!$C$5:$C$154,"base",'10_Data_Sources'!$D$5:$D$154,B$13) -> 0.535 | C7: =SUMIFS('10_Data_Sources'!$E$5:$E$154,'10_Data_Sources'!$A$5:$A$154,"sga_pct_revenue",'10_Data_Sources'!$C$5:$C$154,"base",'10_Data_Sources'!$D$5:$D$154,C$13) -> 0.52125 | D7: =SUMIFS('10_Data_Sources'!$E$5:$E$154,'10_Data_Sources'!$A$5:$A$154,"sga_pct_revenue",'10_Data_Sources'!$C$5:$C$154,"base",'10_Data_Sources'!$D$5:$D$154,D$13) -> 0.5075 | E7: =SUMIFS('10_Data_Sources'!$E$5:$E$154,'10_Data_Sources'!$A$5:$A$154,"sga_pct_revenue",'10_Data_Sources'!$C$5:$C$154,"base",'10_Data_Sources'!$D$5:$D$154,E$13) -> 0.49375 | F7: =SUMIFS('10_Data_Sources'!$E$5:$E$154,'10_Data_Sources'!$A$5:$A$154,"sga_pct_revenue",'10_Data_Sources'!$C$5:$C$154,"base",'10_Data_Sources'!$D$5:$D$154,F$13) -> 0.48
A8: Effective tax rate % | B8: =SUMIFS('10_Data_Sources'!$E$5:$E$154,'10_Data_Sources'!$A$5:$A$154,"effective_tax_rate_pct",'10_Data_Sources'!$C$5:$C$154,"base",'10_Data_Sources'!$D$5:$D$154,B$13) -> 0.08 | C8: =SUMIFS('10_Data_Sources'!$E$5:$E$154,'10_Data_Sources'!$A$5:$A$154,"effective_tax_rate_pct",'10_Data_Sources'!$C$5:$C$154,"base",'10_Data_Sources'!$D$5:$D$154,C$13) -> 0.12 | D8: =SUMIFS('10_Data_Sources'!$E$5:$E$154,'10_Data_Sources'!$A$5:$A$154,"effective_tax_rate_pct",'10_Data_Sources'!$C$5:$C$154,"base",'10_Data_Sources'!$D$5:$D$154,D$13) -> 0.16 | E8: =SUMIFS('10_Data_Sources'!$E$5:$E$154,'10_Data_Sources'!$A$5:$A$154,"effective_tax_rate_pct",'10_Data_Sources'!$C$5:$C$154,"base",'10_Data_Sources'!$D$5:$D$154,E$13) -> 0.2 | F8: =SUMIFS('10_Data_Sources'!$E$5:$E$154,'10_Data_Sources'!$A$5:$A$154,"effective_tax_rate_pct",'10_Data_Sources'!$C$5:$C$154,"base",'10_Data_Sources'!$D$5:$D$154,F$13) -> 0.24
B13: 2026 | C13: =B13+1 -> 2027 | D13: =C13+1 -> 2028 | E13: =D13+1 -> 2029 | F13: =E13+1 -> 2030
A14: Net revenue | B14: ='02_Historical_IS_BS_CF'!$F$5*(1+B5) -> 985252.65 | C14: =B14*(1+C5) -> 1098556.7 | D14: =C14*(1+D5) -> 1208412.4 | E14: =D14*(1+E5) -> 1311127.4 | F14: =E14*(1+F5) -> 1402906.3
A15: Cost of goods sold | B15: =B14*(1-B6) -> 448289.96 | C15: =C14*(1-C6) -> 498470.1 | D15: =D14*(1-D6) -> 546806.6 | E15: =E14*(1-E6) -> 591646.25 | F15: =F14*(1-F6) -> 631307.86
A16: Gross profit | B16: =B14-B15 -> 536962.69 | C16: =C14-C15 -> 600086.6 | D16: =D14-D15 -> 661605.78 | E16: =E14-E15 -> 719481.18 | F16: =F14-F15 -> 771598.49
A17: SG&A | B17: =B14*B7 -> 527110.17 | C17: =C14*C7 -> 572622.68 | D17: =D14*D7 -> 613269.28 | E17: =E14*E7 -> 647369.17 | F17: =F14*F7 -> 673395.05
A18: Operating income (loss) | B18: =B16-B17 -> 9852.5265 | C18: =C16-C17 -> 27463.918 | D18: =D16-D17 -> 48336.495 | E18: =E16-E17 -> 72112.008 | F18: =F16-F17 -> 98203.444
A19: Interest and other income (loss), net | B19: ='02_Historical_IS_BS_CF'!$F$10 -> 8379 | C19: ='02_Historical_IS_BS_CF'!$F$10 -> 8379 | D19: ='02_Historical_IS_BS_CF'!$F$10 -> 8379 | E19: ='02_Historical_IS_BS_CF'!$F$10 -> 8379 | F19: ='02_Historical_IS_BS_CF'!$F$10 -> 8379
A20: Income before taxes | B20: =B18+B19 -> 18231.526 | C20: =C18+C19 -> 35842.918 | D20: =D18+D19 -> 56715.495 | E20: =E18+E19 -> 80491.008 | F20: =F18+F19 -> 106582.44
A21: Net income (loss) | B21: =IF(B20<=0,B20,B20-(B20*B8)) -> 16773.004 | C21: =IF(C20<=0,C20,C20-(C20*C8)) -> 31541.768 | D21: =IF(D20<=0,D20,D20-(D20*D8)) -> 47641.016 | E21: =IF(E20<=0,E20,E20-(E20*E8)) -> 64392.807 | F21: =IF(F20<=0,F20,F20-(F20*F8)) -> 81002.658
A24: BEST CASE
A25: Revenue growth % | B25: =SUMIFS('10_Data_Sources'!$E$5:$E$154,'10_Data_Sources'!$A$5:$A$154,"revenue_growth_pct",'10_Data_Sources'!$C$5:$C$154,"best",'10_Data_Sources'!$D$5:$D$154,B$33) -> 0.15 | C25: =SUMIFS('10_Data_Sources'!$E$5:$E$154,'10_Data_Sources'!$A$5:$A$154,"revenue_growth_pct",'10_Data_Sources'!$C$5:$C$154,"best",'10_Data_Sources'!$D$5:$D$154,C$33) -> 0.14 | D25: =SUMIFS('10_Data_Sources'!$E$5:$E$154,'10_Data_Sources'!$A$5:$A$154,"revenue_growth_pct",'10_Data_Sources'!$C$5:$C$154,"best",'10_Data_Sources'!$D$5:$D$154,D$33) -> 0.13 | E25: =SUMIFS('10_Data_Sources'!$E$5:$E$154,'10_Data_Sources'!$A$5:$A$154,"revenue_growth_pct",'10_Data_Sources'!$C$5:$C$154,"best",'10_Data_Sources'!$D$5:$D$154,E$33) -> 0.12 | F25: =SUMIFS('10_Data_Sources'!$E$5:$E$154,'10_Data_Sources'!$A$5:$A$154,"revenue_growth_pct",'10_Data_Sources'!$C$5:$C$154,"best",'10_Data_Sources'!$D$5:$D$154,F$33) -> 0.11
A26: Gross margin % | B26: =SUMIFS('10_Data_Sources'!$E$5:$E$154,'10_Data_Sources'!$A$5:$A$154,"gross_margin_pct",'10_Data_Sources'!$C$5:$C$154,"best",'10_Data_Sources'!$D$5:$D$154,B$33) -> 0.55 | C26: =SUMIFS('10_Data_Sources'!$E$5:$E$154,'10_Data_Sources'!$A$5:$A$154,"gross_margin_pct",'10_Data_Sources'!$C$5:$C$154,"best",'10_Data_Sources'!$D$5:$D$154,C$33) -> 0.555 | D26: =SUMIFS('10_Data_Sources'!$E$5:$E$154,'10_Data_Sources'!$A$5:$A$154,"gross_margin_pct",'10_Data_Sources'!$C$5:$C$154,"best",'10_Data_Sources'!$D$5:$D$154,D$33) -> 0.56 | E26: =SUMIFS('10_Data_Sources'!$E$5:$E$154,'10_Data_Sources'!$A$5:$A$154,"gross_margin_pct",'10_Data_Sources'!$C$5:$C$154,"best",'10_Data_Sources'!$D$5:$D$154,E$33) -> 0.565 | F26: =SUMIFS('10_Data_Sources'!$E$5:$E$154,'10_Data_Sources'!$A$5:$A$154,"gross_margin_pct",'10_Data_Sources'!$C$5:$C$154,"best",'10_Data_Sources'!$D$5:$D$154,F$33) -> 0.57
A27: SG&A % of revenue | B27: =SUMIFS('10_Data_Sources'!$E$5:$E$154,'10_Data_Sources'!$A$5:$A$154,"sga_pct_revenue",'10_Data_Sources'!$C$5:$C$154,"best",'10_Data_Sources'!$D$5:$D$154,B$33) -> 0.53 | C27: =SUMIFS('10_Data_Sources'!$E$5:$E$154,'10_Data_Sources'!$A$5:$A$154,"sga_pct_revenue",'10_Data_Sources'!$C$5:$C$154,"best",'10_Data_Sources'!$D$5:$D$154,C$33) -> 0.5075 | D27: =SUMIFS('10_Data_Sources'!$E$5:$E$154,'10_Data_Sources'!$A$5:$A$154,"sga_pct_revenue",'10_Data_Sources'!$C$5:$C$154,"best",'10_Data_Sources'!$D$5:$D$154,D$33) -> 0.485 | E27: =SUMIFS('10_Data_Sources'!$E$5:$E$154,'10_Data_Sources'!$A$5:$A$154,"sga_pct_revenue",'10_Data_Sources'!$C$5:$C$154,"best",'10_Data_Sources'!$D$5:$D$154,E$33) -> 0.4625 | F27: =SUMIFS('10_Data_Sources'!$E$5:$E$154,'10_Data_Sources'!$A$5:$A$154,"sga_pct_revenue",'10_Data_Sources'!$C$5:$C$154,"best",'10_Data_Sources'!$D$5:$D$154,F$33) -> 0.44
